I'm sorry, but an uncaught exception occurred.

While running game code:
  File "game/script.rpy", line 107, in script
    show table in_front
Exception: Image 'table' does not accept attributes 'in_front'.

-- Full Traceback ------------------------------------------------------------

Full traceback:
  File "game/script.rpy", line 107, in script
    show table in_front
  File "/Users/kids/Desktop/renpy-8.3.7-sdk/renpy/ast.py", line 1124, in execute
    show_imspec(self.imspec, atl=getattr(self, "atl", None))
  File "/Users/kids/Desktop/renpy-8.3.7-sdk/renpy/ast.py", line 1087, in show_imspec
    renpy.config.show(name,
  File "/Users/kids/Desktop/renpy-8.3.7-sdk/renpy/exports/displayexports.py", line 477, in show
    if not base.find_target() and renpy.config.missing_show:
  File "/Users/kids/Desktop/renpy-8.3.7-sdk/renpy/display/image.py", line 421, in find_target
    self.target = target._duplicate(a)
  File "/Users/kids/Desktop/renpy-8.3.7-sdk/renpy/display/displayable.py", line 249, in _duplicate
    args.extraneous()
  File "/Users/kids/Desktop/renpy-8.3.7-sdk/renpy/display/displayable.py", line 109, in extraneous
    raise Exception("Image '{}' does not accept attributes '{}'.".format(
Exception: Image 'table' does not accept attributes 'in_front'.

macOS-10.16-x86_64-i386-64bit x86_64
Ren'Py 8.3.7.25031702
lily of the valley 1.0
Sun Jul 13 11:26:20 2025
